Workbook

Sheet 202503
A1: Identificador (1) | B1: Ley N° | C1: Desde | D1: Hasta | E1: Desde | F1: Hasta | G1: Unitario | H1: Duplo | I1: Tramo
A2: 202503 | B2: 21751 | C2: 45839 | D2: 45869 | E2: 1 | F2: 620251 | G2: 22007 | H2: 44014 | I2: 1 | J2: enero a junio de 2025
A3: 202503 | B3: 21751 | C3: 45839 | D3: 45869 | E3: 620252 | F3: 905941 | G3: 13505 | H3: 27010 | I3: 2
A4: 202503 | B4: 21751 | C4: 45839 | D4: 45869 | E4: 905942 | F4: 1412957 | G4: 4267 | H4: 8534 | I4: 3
A5: 202503 | B5: 21751 | C5: 45839 | D5: 45869 | E5: 1412958 | F5: 99999999 | G5: 0 | H5: 0 | I5: 4

Sheet 202502
A1: Identificador (1) | B1: Ley N° | C1: Desde | D1: Hasta | E1: Desde | F1: Hasta | G1: Unitario | H1: Duplo | I1: Tramo
A2: 202502 | B2: 21751 | C2: 45778 | D2: 45838 | E2: 1 | F2: 620251 | G2: 22007 | H2: 44014 | I2: 1
A3: 202502 | B3: 21751 | C3: 45778 | D3: 45838 | E3: 620252 | F3: 905941 | G3: 13505 | H3: 27010 | I3: 2
A4: 202502 | B4: 21751 | C4: 45778 | D4: 45838 | E4: 905942 | F4: 1412957 | G4: 4267 | H4: 8534 | I4: 3
A5: 202502 | B5: 21751 | C5: 45778 | D5: 45838 | E5: 1412958 | F5: 99999999 | G5: 0 | H5: 0 | I5: 4

Sheet 202501
A1: Identificador (1) | B1: Ley N° | C1: Desde | D1: Hasta | E1: Desde | F1: Hasta | G1: Unitario | H1: Duplo | I1: Tramo
A2: 202501 | B2: 21578 | C2: 45658 | D2: 45777 | E2: 1 | F2: 598698 | G2: 21243 | H2: 42486 | I2: 1
A3: 202501 | B3: 21578 | C3: 45658 | D3: 45777 | E3: 598699 | F3: 874460 | G3: 13036 | H3: 26072 | I3: 2
A4: 202501 | B4: 21578 | C4: 45658 | D4: 45777 | E4: 874461 | F4: 1363858 | G4: 4119 | H4: 8238 | I4: 3
A5: 202501 | B5: 21578 | C5: 45658 | D5: 45777 | E5: 1363859 | F5: 99999999 | G5: 0 | H5: 0 | I5: 4

Sheet 202401
A1: Identificador (1) | B1: Ley N° | C1: Desde | D1: Hasta | E1: Desde | F1: Hasta | G1: Unitario | H1: Duplo | I1: Tramo
A2: 202401 | B2: 21685 | C2: 45474 | D2: 45657 | E2: 1 | F2: 586227 | G2: 21243 | H2: 42486 | I2: 1
A3: 202401 | B3: 21685 | C3: 45474 | D3: 45657 | E3: 586228 | F3: 856247 | G3: 13036 | H3: 26072 | I3: 2
A4: 202401 | B4: 21685 | C4: 45474 | D4: 45657 | E4: 856248 | F4: 1335450 | G4: 4119 | H4: 8238 | I4: 3
A5: 202401 | B5: 21685 | C5: 45474 | D5: 45657 | E5: 1335451 | F5: 99999999 | G5: 0 | H5: 0 | I5: 4

Sheet Promedio 2025
D1: 1 | E1: 2 | F1: 3 | G1: 4 | H1: 5 | I1: 6 | J1: 7 | K1: 8 | L1: 9 | M1: 10 | N1: 11 | O1: 202503 | P1: 202503
A2: 2 | B2: 1 | C2: rut | D2: RUT | E2: nombre_beneficiario | F2: enero | G2: febrero | H2: marzo | I2: abril | J2: mayo | K2: junio | L2: total | M2: meses | N2: Promedio | O2: tramo | P2: valor
B3: 4759963 | C3: 47599636 | D3: 4759963-6 | E3: TORRES GONZALEZ CARLOS SERGIO | G3: 1427048 | H3: 713524 | I3: 713524 | J3: 713524 | K3: 718091 | L3: 4285711 | M3: 5 | N3: 857142.2 | O3: =IF(AND($N3>='202503'!$E$2,$N3<='202503'!$F$2),'202503'!$I$2,IF(AND($N3>='202503'!$E$3,$N3<='202503'!$F$3),'202503'!$I$3,IF(AND($N3>='202503'!$E$4,$N3<='202503'!$F$4),'202503'!$I$4,IF(AND($N3>='202503'!$E$5,$N3<='202503'!$F$5),'202503'!$I$5,0)))) -> 2 | P3: =IF(AND($N3>='202503'!$E$2,$N3<='202503'!$F$2),'202503'!$G$2,IF(AND($N3>='202503'!$E$3,$N3<='202503'!$F$3),'202503'!$G$3,IF(AND($N3>='202503'!$E$4,$N3<='202503'!$F$4),'202503'!$G$4,IF(AND($N3>='202503'!$E$5,$N3<='202503'!$F$5),'202503'!$G$5,0)))) -> 13505
B4: 5433278 | C4: 54332785 | D4: 5433278-5 | E4: CERDA ROMO ANA MARIA | F4: 3668278 | G4: 3543391 | H4: 5945085 | I4: 3543391 | J4: 3560244 | K4: 6003931 | L4: 26264320 | M4: 6 | N4: 4377386.7 | O4: =IF(AND($N4>='202503'!$E$2,$N4<='202503'!$F$2),'202503'!$I$2,IF(AND($N4>='202503'!$E$3,$N4<='202503'!$F$3),'202503'!$I$3,IF(AND($N4>='202503'!$E$4,$N4<='202503'!$F$4),'202503'!$I$4,IF(AND($N4>='202503'!$E$5,$N4<='202503'!$F$5),'202503'!$I$5,0)))) -> 4 | P4: =IF(AND($N4>='202503'!$E$2,$N4<='202503'!$F$2),'202503'!$G$2,IF(AND($N4>='202503'!$E$3,$N4<='202503'!$F$3),'202503'!$G$3,IF(AND($N4>='202503'!$E$4,$N4<='202503'!$F$4),'202503'!$G$4,IF(AND($N4>='202503'!$E$5,$N4<='202503'!$F$5),'202503'!$G$5,0)))) -> 0
B5: 5511590 | C5: 55115907 | D5: 5511590-7 | E5: HERNANDEZ RAMIREZ JAIME | F5: 4687813 | G5: 4531689 | H5: 7235662 | I5: 4531689 | J5: 4531689 | K5: 7270432 | L5: 32788974 | M5: 6 | N5: 5464829 | O5: =IF(AND($N5>='202503'!$E$2,$N5<='202503'!$F$2),'202503'!$I$2,IF(AND($N5>='202503'!$E$3,$N5<='202503'!$F$3),'202503'!$I$3,IF(AND($N5>='202503'!$E$4,$N5<='202503'!$F$4),'202503'!$I$4,IF(AND($N5>='202503'!$E$5,$N5<='202503'!$F$5),'202503'!$I$5,0)))) -> 4 | P5: =IF(AND($N5>='202503'!$E$2,$N5<='202503'!$F$2),'202503'!$G$2,IF(AND($N5>='202503'!$E$3,$N5<='202503'!$F$3),'202503'!$G$3,IF(AND($N5>='202503'!$E$4,$N5<='202503'!$F$4),'202503'!$G$4,IF(AND($N5>='202503'!$E$5,$N5<='202503'!$F$5),'202503'!$G$5,0)))) -> 0
B6: 5745520 | C6: 57455209 | D6: 5745520-9 | E6: OLIVARES FERNANDEZ DANTE | F6: 2285264 | G6: 2204495 | H6: 4440623 | I6: 2204495 | J6: 2204495 | K6: 4459503 | L6: 17798875 | M6: 6 | N6: 2966479.2 | O6: =IF(AND($N6>='202503'!$E$2,$N6<='202503'!$F$2),'202503'!$I$2,IF(AND($N6>='202503'!$E$3,$N6<='202503'!$F$3),'202503'!$I$3,IF(AND($N6>='202503'!$E$4,$N6<='202503'!$F$4),'202503'!$I$4,IF(AND($N6>='202503'!$E$5,$N6<='202503'!$F$5),'202503'!$I$5,0)))) -> 4 | P6: =IF(AND($N6>='202503'!$E$2,$N6<='202503'!$F$2),'202503'!$G$2,IF(AND($N6>='202503'!$E$3,$N6<='202503'!$F$3),'202503'!$G$3,IF(AND($N6>='202503'!$E$4,$N6<='202503'!$F$4),'202503'!$G$4,IF(AND($N6>='202503'!$E$5,$N6<='202503'!$F$5),'202503'!$G$5,0)))) -> 0
B7: 6069040 | C7: 60690405 | D7: 6069040-5 | E7: MARIN LOPEZ SERGIO | F7: 3175966 | G7: 3064995 | H7: 5459619 | I7: 3064995 | J7: 3064995 | K7: 5484344 | L7: 23314914 | M7: 6 | N7: 3885819 | O7: =IF(AND($N7>='202503'!$E$2,$N7<='202503'!$F$2),'202503'!$I$2,IF(AND($N7>='202503'!$E$3,$N7<='202503'!$F$3),'202503'!$I$3,IF(AND($N7>='202503'!$E$4,$N7<='202503'!$F$4),'202503'!$I$4,IF(AND($N7>='202503'!$E$5,$N7<='202503'!$F$5),'202503'!$I$5,0)))) -> 4 | P7: =IF(AND($N7>='202503'!$E$2,$N7<='202503'!$F$2),'202503'!$G$2,IF(AND($N7>='202503'!$E$3,$N7<='202503'!$F$3),'202503'!$G$3,IF(AND($N7>='202503'!$E$4,$N7<='202503'!$F$4),'202503'!$G$4,IF(AND($N7>='202503'!$E$5,$N7<='202503'!$F$5),'202503'!$G$5,0)))) -> 0
B8: 6296248 | C8: 62962488 | D8: 6296248-8 | E8: CUCUMIDES LITIN CRISTO HERNAN | F8: 2807343 | G8: 2807343 | H8: 5159685 | I8: 2807343 | J8: 2807343 | K8: 5188582 | L8: 21577639 | M8: 6 | N8: 3596273.2 | O8: =IF(AND($N8>='202503'!$E$2,$N8<='202503'!$F$2),'202503'!$I$2,IF(AND($N8>='202503'!$E$3,$N8<='202503'!$F$3),'202503'!$I$3,IF(AND($N8>='202503'!$E$4,$N8<='202503'!$F$4),'202503'!$I$4,IF(AND($N8>='202503'!$E$5,$N8<='202503'!$F$5),'202503'!$I$5,0)))) -> 4 | P8: =IF(AND($N8>='202503'!$E$2,$N8<='202503'!$F$2),'202503'!$G$2,IF(AND($N8>='202503'!$E$3,$N8<='202503'!$F$3),'202503'!$G$3,IF(AND($N8>='202503'!$E$4,$N8<='202503'!$F$4),'202503'!$G$4,IF(AND($N8>='202503'!$E$5,$N8<='202503'!$F$5),'202503'!$G$5,0)))) -> 0
B9: 6543718 | C9: 06543718K | D9: 6543718-K | E9: CAMPOS BURGOS JUAN GUILLERMO | F9: 3386571 | G9: 3268887 | H9: 5739708 | I9: 3285740 | J9: 3285740 | K9: 5796921 | L9: 24763567 | M9: 6 | N9: 4127261.2 | O9: =IF(AND($N9>='202503'!$E$2,$N9<='202503'!$F$2),'202503'!$I$2,IF(AND($N9>='202503'!$E$3,$N9<='202503'!$F$3),'202503'!$I$3,IF(AND($N9>='202503'!$E$4,$N9<='202503'!$F$4),'202503'!$I$4,IF(AND($N9>='202503'!$E$5,$N9<='202503'!$F$5),'202503'!$I$5,0)))) -> 4 | P9: =IF(AND($N9>='202503'!$E$2,$N9<='202503'!$F$2),'202503'!$G$2,IF(AND($N9>='202503'!$E$3,$N9<='202503'!$F$3),'202503'!$G$3,IF(AND($N9>='202503'!$E$4,$N9<='202503'!$F$4),'202503'!$G$4,IF(AND($N9>='202503'!$E$5,$N9<='202503'!$F$5),'202503'!$G$5,0)))) -> 0
B10: 6667887 | C10: 66678873 | D10: 6667887-3 | E10: CANO MATUS PATRICIO ANDRES | F10: 3004556 | G10: 2899845 | H10: 5135849 | I10: 2899845 | J10: 2899845 | K10: 5159179 | L10: 21999119 | M10: 6 | N10: 3666519.8 | O10: =IF(AND($N10>='202503'!$E$2,$N10<='202503'!$F$2),'202503'!$I$2,IF(AND($N10>='202503'!$E$3,$N10<='202503'!$F$3),'202503'!$I$3,IF(AND($N10>='202503'!$E$4,$N10<='202503'!$F$4),'202503'!$I$4,IF(AND($N10>='202503'!$E$5,$N10<='202503'!$F$5),'202503'!$I$5,0)))) -> 4 | P10: =IF(AND($N10>='202503'!$E$2,$N10<='202503'!$F$2),'202503'!$G$2,IF(AND($N10>='202503'!$E$3,$N10<='202503'!$F$3),'202503'!$G$3,IF(AND($N10>='202503'!$E$4,$N10<='202503'!$F$4),'202503'!$G$4,IF(AND($N10>='202503'!$E$5,$N10<='202503'!$F$5),'202503'!$G$5,0)))) -> 0
B11: 6974011 | C11: 69740111 | D11: 6974011-1 | E11: BUENO ESPINDOLA GLADYS TERESA | F11: 2196490 | G11: 2117780 | H11: 4003142 | I11: 2117780 | J11: 2117780 | K11: 4020719 | L11: 16573691 | M11: 6 | N11: 2762281.8 | O11: =IF(AND($N11>='202503'!$E$2,$N11<='202503'!$F$2),'202503'!$I$2,IF(AND($N11>='202503'!$E$3,$N11<='202503'!$F$3),'202503'!$I$3,IF(AND($N11>='202503'!$E$4,$N11<='202503'!$F$4),'202503'!$I$4,IF(AND($N11>='202503'!$E$5,$N11<='202503'!$F$5),'202503'!$I$5,0)))) -> 4 | P11: =IF(AND($N11>='202503'!$E$2,$N11<='202503'!$F$2),'202503'!$G$2,IF(AND($N11>='202503'!$E$3,$N11<='202503'!$F$3),'202503'!$G$3,IF(AND($N11>='202503'!$E$4,$N11<='202503'!$F$4),'202503'!$G$4,IF(AND($N11>='202503'!$E$5,$N11<='202503'!$F$5),'202503'!$G$5,0)))) -> 0
B12: 6988957 | C12: 69889573 | D12: 6988957-3 | E12: AVALOS OYARZUN MARIA SOLEDAD | F12: 3175966 | G12: 3064995 | H12: 5459619 | I12: 3064995 | J12: 3064995 | K12: 5484344 | L12: 23314914 | M12: 6 | N12: 3885819 | O12: =IF(AND($N12>='202503'!$E$2,$N12<='202503'!$F$2),'202503'!$I$2,IF(AND($N12>='202503'!$E$3,$N12<='202503'!$F$3),'202503'!$I$3,IF(AND($N12>='202503'!$E$4,$N12<='202503'!$F$4),'202503'!$I$4,IF(AND($N12>='202503'!$E$5,$N12<='202503'!$F$5),'202503'!$I$5,0)))) -> 4 | P12: =IF(AND($N12>='202503'!$E$2,$N12<='202503'!$F$2),'202503'!$G$2,IF(AND($N12>='202503'!$E$3,$N12<='202503'!$F$3),'202503'!$G$3,IF(AND($N12>='202503'!$E$4,$N12<='202503'!$F$4),'202503'!$G$4,IF(AND($N12>='202503'!$E$5,$N12<='202503'!$F$5),'202503'!$G$5,0)))) -> 0
B13: 7018093 | C13: 70180936 | D13: 7018093-6 | E13: GAJARDO BEROIZA JORGE MIGUEL | F13: 2106062 | G13: 2032811 | H13: 3525844 | I13: 2032811 | J13: 2032811 | K13: 3542040 | L13: 15272379 | M13: 6 | N13: 2545396.5 | O13: =IF(AND($N13>='202503'!$E$2,$N13<='202503'!$F$2),'202503'!$I$2,IF(AND($N13>='202503'!$E$3,$N13<='202503'!$F$3),'202503'!$I$3,IF(AND($N13>='202503'!$E$4,$N13<='202503'!$F$4),'202503'!$I$4,IF(AND($N13>='202503'!$E$5,$N13<='202503'!$F$5),'202503'!$I$5,0)))) -> 4 | P13: =IF(AND($N13>='202503'!$E$2,$N13<='202503'!$F$2),'202503'!$G$2,IF(AND($N13>='202503'!$E$3,$N13<='202503'!$F$3),'202503'!$G$3,IF(AND($N13>='202503'!$E$4,$N13<='202503'!$F$4),'202503'!$G$4,IF(AND($N13>='202503'!$E$5,$N13<='202503'!$F$5),'202503'!$G$5,0)))) -> 0
B14: 7041505 | C14: 70415054 | D14: 7041505-4 | E14: TORO SANCHEZ MARIA ANGELICA | F14: 3438287 | G14: 3319446 | H14: 5753697 | I14: 3319446 | J14: 3319446 | K14: 5804581 | L14: 24954903 | M14: 6 | N14: 4159150.5 | O14: =IF(AND($N14>='202503'!$E$2,$N14<='202503'!$F$2),'202503'!$I$2,IF(AND($N14>='202503'!$E$3,$N14<='202503'!$F$3),'202503'!$I$3,IF(AND($N14>='202503'!$E$4,$N14<='202503'!$F$4),'202503'!$I$4,IF(AND($N14>='202503'!$E$5,$N14<='202503'!$F$5),'202503'!$I$5,0)))) -> 4 | P14: =IF(AND($N14>='202503'!$E$2,$N14<='202503'!$F$2),'202503'!$G$2,IF(AND($N14>='202503'!$E$3,$N14<='202503'!$F$3),'202503'!$G$3,IF(AND($N14>='202503'!$E$4,$N14<='202503'!$F$4),'202503'!$G$4,IF(AND($N14>='202503'!$E$5,$N14<='202503'!$F$5),'202503'!$G$5,0)))) -> 0
B15: 7045235 | C15: 70452359 | D15: 7045235-9 | E15: GONZALEZ MALDONADO DAVID ANDRES | F15: 2106062 | G15: 2032811 | H15: 3471134 | I15: 2032811 | J15: 2032811 | K15: 3487212 | L15: 15162841 | M15: 6 | N15: 2527140.2 | O15: =IF(AND($N15>='202503'!$E$2,$N15<='202503'!$F$2),'202503'!$I$2,IF(AND($N15>='202503'!$E$3,$N15<='202503'!$F$3),'202503'!$I$3,IF(AND($N15>='202503'!$E$4,$N15<='202503'!$F$4),'202503'!$I$4,IF(AND($N15>='202503'!$E$5,$N15<='202503'!$F$5),'202503'!$I$5,0)))) -> 4 | P15: =IF(AND($N15>='202503'!$E$2,$N15<='202503'!$F$2),'202503'!$G$2,IF(AND($N15>='202503'!$E$3,$N15<='202503'!$F$3),'202503'!$G$3,IF(AND($N15>='202503'!$E$4,$N15<='202503'!$F$4),'202503'!$G$4,IF(AND($N15>='202503'!$E$5,$N15<='202503'!$F$5),'202503'!$G$5,0)))) -> 0
B16: 7047392 | C16: 70473925 | D16: 7047392-5 | E16: HERNANDEZ ARENAS OSVALDO | F16: 2374547 | G16: 2292217 | H16: 3900905 | I16: 2292217 | J16: 2292217 | K16: 3919006 | L16: 17071109 | M16: 6 | N16: 2845184.8 | O16: =IF(AND($N16>='202503'!$E$2,$N16<='202503'!$F$2),'202503'!$I$2,IF(AND($N16>='202503'!$E$3,$N16<='202503'!$F$3),'202503'!$I$3,IF(AND($N16>='202503'!$E$4,$N16<='202503'!$F$4),'202503'!$I$4,IF(AND($N16>='202503'!$E$5,$N16<='202503'!$F$5),'202503'!$I$5,0)))) -> 4 | P16: =IF(AND($N16>='202503'!$E$2,$N16<='202503'!$F$2),'202503'!$G$2,IF(AND($N16>='202503'!$E$3,$N16<='202503'!$F$3),'202503'!$G$3,IF(AND($N16>='202503'!$E$4,$N16<='202503'!$F$4),'202503'!$G$4,IF(AND($N16>='202503'!$E$5,$N16<='202503'!$F$5),'202503'!$G$5,0)))) -> 0
B17: 7070639 | C17: 70706393 | D17: 7070639-3 | E17: TRONCOSO RODRIGUEZ MOISES RECAREDO | F17: 1144851 | G17: 1103408 | H17: 2113106 | I17: 1103408 | J17: 1103408 | K17: 2122324 | L17: 8690505 | M17: 6 | N17: 1448417.5 | O17: =IF(AND($N17>='202503'!$E$2,$N17<='202503'!$F$2),'202503'!$I$2,IF(AND($N17>='202503'!$E$3,$N17<='202503'!$F$3),'202503'!$I$3,IF(AND($N17>='202503'!$E$4,$N17<='202503'!$F$4),'202503'!$I$4,IF(AND($N17>='202503'!$E$5,$N17<='202503'!$F$5),'202503'!$I$5,0)))) -> 4 | P17: =IF(AND($N17>='202503'!$E$2,$N17<='202503'!$F$2),'202503'!$G$2,IF(AND($N17>='202503'!$E$3,$N17<='202503'!$F$3),'202503'!$G$3,IF(AND($N17>='202503'!$E$4,$N17<='202503'!$F$4),'202503'!$G$4,IF(AND($N17>='202503'!$E$5,$N17<='202503'!$F$5),'202503'!$G$5,0)))) -> 0
B18: 7077689 | C18: 70776898 | D18: 7077689-8 | E18: RODRIGUEZ GONZALEZ XIMENA EUGENIA | F18: 2833736 | G18: 2735706 | H18: 4632464 | I18: 2735706 | J18: 2735706 | K18: 4654020 | L18: 20327338 | M18: 6 | N18: 3387889.7 | O18: =IF(AND($N18>='202503'!$E$2,$N18<='202503'!$F$2),'202503'!$I$2,IF(AND($N18>='202503'!$E$3,$N18<='202503'!$F$3),'202503'!$I$3,IF(AND($N18>='202503'!$E$4,$N18<='202503'!$F$4),'202503'!$I$4,IF(AND($N18>='202503'!$E$5,$N18<='202503'!$F$5),'202503'!$I$5,0)))) -> 4 | P18: =IF(AND($N18>='202503'!$E$2,$N18<='202503'!$F$2),'202503'!$G$2,IF(AND($N18>='202503'!$E$3,$N18<='202503'!$F$3),'202503'!$G$3,IF(AND($N18>='202503'!$E$4,$N18<='202503'!$F$4),'202503'!$G$4,IF(AND($N18>='202503'!$E$5,$N18<='202503'!$F$5),'202503'!$G$5,0)))) -> 0
B19: 7086238 | C19: 70862387 | D19: 7086238-7 | E19: FIGUEROA LINDEMANN RAMON ANTONIO | F19: 996778 | G19: 970434 | H19: 1938978 | I19: 970434 | J19: 970434 | K19: 1947255 | L19: 7794313 | M19: 6 | N19: 1299052.2 | O19: =IF(AND($N19>='202503'!$E$2,$N19<='202503'!$F$2),'202503'!$I$2,IF(AND($N19>='202503'!$E$3,$N19<='202503'!$F$3),'202503'!$I$3,IF(AND($N19>='202503'!$E$4,$N19<='202503'!$F$4),'202503'!$I$4,IF(AND($N19>='202503'!$E$5,$N19<='202503'!$F$5),'202503'!$I$5,0)))) -> 3 | P19: =IF(AND($N19>='202503'!$E$2,$N19<='202503'!$F$2),'202503'!$G$2,IF(AND($N19>='202503'!$E$3,$N19<='202503'!$F$3),'202503'!$G$3,IF(AND($N19>='202503'!$E$4,$N19<='202503'!$F$4),'202503'!$G$4,IF(AND($N19>='202503'!$E$5,$N19<='202503'!$F$5),'202503'!$G$5,0)))) -> 4267
B20: 7107091 | C20: 71070913 | D20: 7107091-3 | E20: DIAZ DIAZ MONICA DE LAS MERCEDES | F20: 2834075 | G20: 2732168 | H20: 5167318 | I20: 2746550 | J20: 2746550 | K20: 5215628 | L20: 21442289 | M20: 6 | N20: 3573714.8 | O20: =IF(AND($N20>='202503'!$E$2,$N20<='202503'!$F$2),'202503'!$I$2,IF(AND($N20>='202503'!$E$3,$N20<='202503'!$F$3),'202503'!$I$3,IF(AND($N20>='202503'!$E$4,$N20<='202503'!$F$4),'202503'!$I$4,IF(AND($N20>='202503'!$E$5,$N20<='202503'!$F$5),'202503'!$I$5,0)))) -> 4 | P20: =IF(AND($N20>='202503'!$E$2,$N20<='202503'!$F$2),'202503'!$G$2,IF(AND($N20>='202503'!$E$3,$N20<='202503'!$F$3),'202503'!$G$3,IF(AND($N20>='202503'!$E$4,$N20<='202503'!$F$4),'202503'!$G$4,IF(AND($N20>='202503'!$E$5,$N20<='202503'!$F$5),'202503'!$G$5,0)))) -> 0
B21: 7159683 | C21: 71596834 | D21: 7159683-4 | E21: JIMENEZ JIMENEZ MYRIAM DEL CARMEN | F21: 1275975 | G21: 1228301 | H21: 2514627 | I21: 1228301 | J21: 1228301 | K21: 2525233 | L21: 10000738 | M21: 6 | N21: 1666789.7 | O21: =IF(AND($N21>='202503'!$E$2,$N21<='202503'!$F$2),'202503'!$I$2,IF(AND($N21>='202503'!$E$3,$N21<='202503'!$F$3),'202503'!$I$3,IF(AND($N21>='202503'!$E$4,$N21<='202503'!$F$4),'202503'!$I$4,IF(AND($N21>='202503'!$E$5,$N21<='202503'!$F$5),'202503'!$I$5,0)))) -> 4 | P21: =IF(AND($N21>='202503'!$E$2,$N21<='202503'!$F$2),'202503'!$G$2,IF(AND($N21>='202503'!$E$3,$N21<='202503'!$F$3),'202503'!$G$3,IF(AND($N21>='202503'!$E$4,$N21<='202503'!$F$4),'202503'!$G$4,IF(AND($N21>='202503'!$E$5,$N21<='202503'!$F$5),'202503'!$G$5,0)))) -> 0
B22: 7179865 | C22: 71798658 | D22: 7179865-8 | E22: VILLALOBOS CASTRO VICTOR | F22: 1043214 | G22: 1005437 | H22: 1926854 | I22: 1005437 | J22: 1005437 | K22: 1935254 | L22: 7921633 | M22: 6 | N22: 1320272.2 | O22: =IF(AND($N22>='202503'!$E$2,$N22<='202503'!$F$2),'202503'!$I$2,IF(AND($N22>='202503'!$E$3,$N22<='202503'!$F$3),'202503'!$I$3,IF(AND($N22>='202503'!$E$4,$N22<='202503'!$F$4),'202503'!$I$4,IF(AND($N22>='202503'!$E$5,$N22<='202503'!$F$5),'202503'!$I$5,0)))) -> 3 | P22: =IF(AND($N22>='202503'!$E$2,$N22<='202503'!$F$2),'202503'!$G$2,IF(AND($N22>='202503'!$E$3,$N22<='202503'!$F$3),'202503'!$G$3,IF(AND($N22>='202503'!$E$4,$N22<='202503'!$F$4),'202503'!$G$4,IF(AND($N22>='202503'!$E$5,$N22<='202503'!$F$5),'202503'!$G$5,0)))) -> 4267
B23: 7194520 | C23: 71945200 | D23: 7194520-0 | E23: DE LA FUENTE NAHMIAS MYRIAM EUGENIA | F23: 1100952 | G23: 1061120 | H23: 2029664 | L23: 4191736 | M23: 3 | N23: 1397245.3 | O23: =IF(AND($N23>='202503'!$E$2,$N23<='202503'!$F$2),'202503'!$I$2,IF(AND($N23>='202503'!$E$3,$N23<='202503'!$F$3),'202503'!$I$3,IF(AND($N23>='202503'!$E$4,$N23<='202503'!$F$4),'202503'!$I$4,IF(AND($N23>='202503'!$E$5,$N23<='202503'!$F$5),'202503'!$I$5,0)))) -> 3 | P23: =IF(AND($N23>='202503'!$E$2,$N23<='202503'!$F$2),'202503'!$G$2,IF(AND($N23>='202503'!$E$3,$N23<='202503'!$F$3),'202503'!$G$3,IF(AND($N23>='202503'!$E$4,$N23<='202503'!$F$4),'202503'!$G$4,IF(AND($N23>='202503'!$E$5,$N23<='202503'!$F$5),'202503'!$G$5,0)))) -> 4267
B24: 7199880 | C24: 71998800 | D24: 7199880-0 | E24: VALDENEGRO HERRADA MARCELINO | F24: 2440460 | G24: 2356286 | H24: 4059144 | I24: 2356286 | J24: 2356286 | K24: 4077856 | L24: 17646318 | M24: 6 | N24: 2941053 | O24: =IF(AND($N24>='202503'!$E$2,$N24<='202503'!$F$2),'202503'!$I$2,IF(AND($N24>='202503'!$E$3,$N24<='202503'!$F$3),'202503'!$I$3,IF(AND($N24>='202503'!$E$4,$N24<='202503'!$F$4),'202503'!$I$4,IF(AND($N24>='202503'!$E$5,$N24<='202503'!$F$5),'202503'!$I$5,0)))) -> 4 | P24: =IF(AND($N24>='202503'!$E$2,$N24<='202503'!$F$2),'202503'!$G$2,IF(AND($N24>='202503'!$E$3,$N24<='202503'!$F$3),'202503'!$G$3,IF(AND($N24>='202503'!$E$4,$N24<='202503'!$F$4),'202503'!$G$4,IF(AND($N24>='202503'!$E$5,$N24<='202503'!$F$5),'202503'!$G$5,0)))) -> 0
B25: 7312426 | C25: 73124263 | D25: 7312426-3 | E25: FRIESER ROBLERO MARTA FRESIA | F25: 1144456 | G25: 1103408 | H25: 2071952 | I25: 1103408 | J25: 1103408 | K25: 2081082 | L25: 8607714 | M25: 6 | N25: 1434619 | O25: =IF(AND($N25>='202503'!$E$2,$N25<='202503'!$F$2),'202503'!$I$2,IF(AND($N25>='202503'!$E$3,$N25<='202503'!$F$3),'202503'!$I$3,IF(AND($N25>='202503'!$E$4,$N25<='202503'!$F$4),'202503'!$I$4,IF(AND($N25>='202503'!$E$5,$N25<='202503'!$F$5),'202503'!$I$5,0)))) -> 4 | P25: =IF(AND($N25>='202503'!$E$2,$N25<='202503'!$F$2),'202503'!$G$2,IF(AND($N25>='202503'!$E$3,$N25<='202503'!$F$3),'202503'!$G$3,IF(AND($N25>='202503'!$E$4,$N25<='202503'!$F$4),'202503'!$G$4,IF(AND($N25>='202503'!$E$5,$N25<='202503'!$F$5),'202503'!$G$5,0)))) -> 0
B26: 7341772 | C26: 73417724 | D26: 7341772-4 | E26: ECHAURREN MEYERHOLZ MAX ALEJANDRO | F26: 3175966 | G26: 3064995 | H26: 5459619 | I26: 3064995 | J26: 3064995 | K26: 5484344 | L26: 23314914 | M26: 6 | N26: 3885819 | O26: =IF(AND($N26>='202503'!$E$2,$N26<='202503'!$F$2),'202503'!$I$2,IF(AND($N26>='202503'!$E$3,$N26<='202503'!$F$3),'202503'!$I$3,IF(AND($N26>='202503'!$E$4,$N26<='202503'!$F$4),'202503'!$I$4,IF(AND($N26>='202503'!$E$5,$N26<='202503'!$F$5),'202503'!$I$5,0)))) -> 4 | P26: =IF(AND($N26>='202503'!$E$2,$N26<='202503'!$F$2),'202503'!$G$2,IF(AND($N26>='202503'!$E$3,$N26<='202503'!$F$3),'202503'!$G$3,IF(AND($N26>='202503'!$E$4,$N26<='202503'!$F$4),'202503'!$G$4,IF(AND($N26>='202503'!$E$5,$N26<='202503'!$F$5),'202503'!$G$5,0)))) -> 0
B27: 7361173 | C27: 73611733 | D27: 7361173-3 | E27: ALVAREZ BULACIO ORLANDO ANTONIO RICARDO | F27: 3678821 | G27: 3550688 | H27: 6252893 | I27: 3550688 | J27: 3550688 | K27: 6281382 | L27: 26865160 | M27: 6 | N27: 4477526.7 | O27: =IF(AND($N27>='202503'!$E$2,$N27<='202503'!$F$2),'202503'!$I$2,IF(AND($N27>='202503'!$E$3,$N27<='202503'!$F$3),'202503'!$I$3,IF(AND($N27>='202503'!$E$4,$N27<='202503'!$F$4),'202503'!$I$4,IF(AND($N27>='202503'!$E$5,$N27<='202503'!$F$5),'202503'!$I$5,0)))) -> 4 | P27: =IF(AND($N27>='202503'!$E$2,$N27<='202503'!$F$2),'202503'!$G$2,IF(AND($N27>='202503'!$E$3,$N27<='202503'!$F$3),'202503'!$G$3,IF(AND($N27>='202503'!$E$4,$N27<='202503'!$F$4),'202503'!$G$4,IF(AND($N27>='202503'!$E$5,$N27<='202503'!$F$5),'202503'!$G$5,0)))) -> 0
B28: 7405761 | C28: 74057616 | D28: 7405761-6 | E28: OSORIO GOMEZ ROLANDO ISMAEL | F28: 2339102 | G28: 2254504 | H28: 4309132 | I28: 2254504 | J28: 2254504 | K28: 4327944 | L28: 17739690 | M28: 6 | N28: 2956615 | O28: =IF(AND($N28>='202503'!$E$2,$N28<='202503'!$F$2),'202503'!$I$2,IF(AND($N28>='202503'!$E$3,$N28<='202503'!$F$3),'202503'!$I$3,IF(AND($N28>='202503'!$E$4,$N28<='202503'!$F$4),'202503'!$I$4,IF(AND($N28>='202503'!$E$5,$N28<='202503'!$F$5),'202503'!$I$5,0)))) -> 4 | P28: =IF(AND($N28>='202503'!$E$2,$N28<='202503'!$F$2),'202503'!$G$2,IF(AND($N28>='202503'!$E$3,$N28<='202503'!$F$3),'202503'!$G$3,IF(AND($N28>='202503'!$E$4,$N28<='202503'!$F$4),'202503'!$G$4,IF(AND($N28>='202503'!$E$5,$N28<='202503'!$F$5),'202503'!$G$5,0)))) -> 0
B29: 7411441 | C29: 74114415 | D29: 7411441-5 | E29: DIAZ ALVAREZ MONICA IVELISSE | F29: 3092230 | G29: 2982618 | H29: 5470873 | I29: 2982618 | J29: 2982618 | K29: 5519714 | L29: 23030671 | M29: 6 | N29: 3838445.2 | O29: =IF(AND($N29>='202503'!$E$2,$N29<='202503'!$F$2),'202503'!$I$2,IF(AND($N29>='202503'!$E$3,$N29<='202503'!$F$3),'202503'!$I$3,IF(AND($N29>='202503'!$E$4,$N29<='202503'!$F$4),'202503'!$I$4,IF(AND($N29>='202503'!$E$5,$N29<='202503'!$F$5),'202503'!$I$5,0)))) -> 4 | P29: =IF(AND($N29>='202503'!$E$2,$N29<='202503'!$F$2),'202503'!$G$2,IF(AND($N29>='202503'!$E$3,$N29<='202503'!$F$3),'202503'!$G$3,IF(AND($N29>='202503'!$E$4,$N29<='202503'!$F$4),'202503'!$G$4,IF(AND($N29>='202503'!$E$5,$N29<='202503'!$F$5),'202503'!$G$5,0)))) -> 0
B30: 7433699 | C30: 07433699K | D30: 7433699-K | E30: EVERT HURTADO AUGUSTO ELIAS MOISES | F30: 1023072 | G30: 985859 | H30: 1907276 | I30: 985859 | J30: 985859 | K30: 1915552 | L30: 7803477 | M30: 6 | N30: 1300579.5 | O30: =IF(AND($N30>='202503'!$E$2,$N30<='202503'!$F$2),'202503'!$I$2,IF(AND($N30>='202503'!$E$3,$N30<='202503'!$F$3),'202503'!$I$3,IF(AND($N30>='202503'!$E$4,$N30<='202503'!$F$4),'202503'!$I$4,IF(AND($N30>='202503'!$E$5,$N30<='202503'!$F$5),'202503'!$I$5,0)))) -> 3 | P30: =IF(AND($N30>='202503'!$E$2,$N30<='202503'!$F$2),'202503'!$G$2,IF(AND($N30>='202503'!$E$3,$N30<='202503'!$F$3),'202503'!$G$3,IF(AND($N30>='202503'!$E$4,$N30<='202503'!$F$4),'202503'!$G$4,IF(AND($N30>='202503'!$E$5,$N30<='202503'!$F$5),'202503'!$G$5,0)))) -> 4267
B31: 7443475 | C31: 74434754 | D31: 7443475-4 | E31: HOLZAPFEL PEÑA MOYRA FELICIA | F31: 2789881 | G31: 2689020 | H31: 5135301 | I31: 2689020 | J31: 2689020 | K31: 5157730 | L31: 21149972 | M31: 6 | N31: 3524995.3 | O31: =IF(AND($N31>='202503'!$E$2,$N31<='202503'!$F$2),'202503'!$I$2,IF(AND($N31>='202503'!$E$3,$N31<='202503'!$F$3),'202503'!$I$3,IF(AND($N31>='202503'!$E$4,$N31<='202503'!$F$4),'202503'!$I$4,IF(AND($N31>='202503'!$E$5,$N31<='202503'!$F$5),'202503'!$I$5,0)))) -> 4 | P31: =IF(AND($N31>='202503'!$E$2,$N31<='202503'!$F$2),'202503'!$G$2,IF(AND($N31>='202503'!$E$3,$N31<='202503'!$F$3),'202503'!$G$3,IF(AND($N31>='202503'!$E$4,$N31<='202503'!$F$4),'202503'!$G$4,IF(AND($N31>='202503'!$E$5,$N31<='202503'!$F$5),'202503'!$G$5,0)))) -> 0
B32: 7477048 | C32: 74770487 | D32: 7477048-7 | E32: CASTAÑEDA ARRIAGADA MARITZA DEL CARMEN | F32: 2590984 | G32: 2497572 | H32: 4738833 | I32: 2497572 | J32: 2497572 | K32: 4759601 | L32: 19582134 | M32: 6 | N32: 3263689 | O32: =IF(AND($N32>='202503'!$E$2,$N32<='202503'!$F$2),'202503'!$I$2,IF(AND($N32>='202503'!$E$3,$N32<='202503'!$F$3),'202503'!$I$3,IF(AND($N32>='202503'!$E$4,$N32<='202503'!$F$4),'202503'!$I$4,IF(AND($N32>='202503'!$E$5,$N32<='202503'!$F$5),'202503'!$I$5,0)))) -> 4 | P32: =IF(AND($N32>='202503'!$E$2,$N32<='202503'!$F$2),'202503'!$G$2,IF(AND($N32>='202503'!$E$3,$N32<='202503'!$F$3),'202503'!$G$3,IF(AND($N32>='202503'!$E$4,$N32<='202503'!$F$4),'202503'!$G$4,IF(AND($N32>='202503'!$E$5,$N32<='202503'!$F$5),'202503'!$G$5,0)))) -> 0
B33: 7553617 | C33: 75536178 | D33: 7553617-8 | E33: GALAN MARTINEZ JORGE ALBERTO | F33: 3004556 | G33: 2899845 | H33: 5135849 | I33: 2899845 | J33: 2899845 | K33: 5159179 | L33: 21999119 | M33: 6 | N33: 3666519.8 | O33: =IF(AND($N33>='202503'!$E$2,$N33<='202503'!$F$2),'202503'!$I$2,IF(AND($N33>='202503'!$E$3,$N33<='202503'!$F$3),'202503'!$I$3,IF(AND($N33>='202503'!$E$4,$N33<='202503'!$F$4),'202503'!$I$4,IF(AND($N33>='202503'!$E$5,$N33<='202503'!$F$5),'202503'!$I$5,0)))) -> 4 | P33: =IF(AND($N33>='202503'!$E$2,$N33<='202503'!$F$2),'202503'!$G$2,IF(AND($N33>='202503'!$E$3,$N33<='202503'!$F$3),'202503'!$G$3,IF(AND($N33>='202503'!$E$4,$N33<='202503'!$F$4),'202503'!$G$4,IF(AND($N33>='202503'!$E$5,$N33<='202503'!$F$5),'202503'!$G$5,0)))) -> 0
B34: 7629937 | C34: 76299374 | D34: 7629937-4 | E34: DIAZ VARGAS CRISTIAN GONZALO | F34: 3812676 | G34: 3680799 | H34: 6383004 | I34: 3680799 | J34: 3680799 | K34: 6412325 | L34: 27650402 | M34: 6 | N34: 4608400.3 | O34: =IF(AND($N34>='202503'!$E$2,$N34<='202503'!$F$2),'202503'!$I$2,IF(AND($N34>='202503'!$E$3,$N34<='202503'!$F$3),'202503'!$I$3,IF(AND($N34>='202503'!$E$4,$N34<='202503'!$F$4),'202503'!$I$4,IF(AND($N34>='202503'!$E$5,$N34<='202503'!$F$5),'202503'!$I$5,0)))) -> 4 | P34: =IF(AND($N34>='202503'!$E$2,$N34<='202503'!$F$2),'202503'!$G$2,IF(AND($N34>='202503'!$E$3,$N34<='202503'!$F$3),'202503'!$G$3,IF(AND($N34>='202503'!$E$4,$N34<='202503'!$F$4),'202503'!$G$4,IF(AND($N34>='202503'!$E$5,$N34<='202503'!$F$5),'202503'!$G$5,0)))) -> 0
B35: 7632596 | C35: 76325960 | D35: 7632596-0 | E35: SIERRA ESPINOZA RUBEN ELIECER | F35: 3175966 | G35: 3064995 | H35: 5459619 | I35: 3064995 | J35: 3064995 | K35: 5484344 | L35: 23314914 | M35: 6 | N35: 3885819 | O35: =IF(AND($N35>='202503'!$E$2,$N35<='202503'!$F$2),'202503'!$I$2,IF(AND($N35>='202503'!$E$3,$N35<='202503'!$F$3),'202503'!$I$3,IF(AND($N35>='202503'!$E$4,$N35<='202503'!$F$4),'202503'!$I$4,IF(AND($N35>='202503'!$E$5,$N35<='202503'!$F$5),'202503'!$I$5,0)))) -> 4 | P35: =IF(AND($N35>='202503'!$E$2,$N35<='202503'!$F$2),'202503'!$G$2,IF(AND($N35>='202503'!$E$3,$N35<='202503'!$F$3),'202503'!$G$3,IF(AND($N35>='202503'!$E$4,$N35<='202503'!$F$4),'202503'!$G$4,IF(AND($N35>='202503'!$E$5,$N35<='202503'!$F$5),'202503'!$G$5,0)))) -> 0
B36: 7642033 | C36: 76420335 | D36: 7642033-5 | E36: JAUREGUI FERNANDEZ PATRICIO JORGE | F36: 742565 | G36: 702585 | H36: 1410384 | I36: 715554 | J36: 715554 | K36: 1416389 | L36: 5703031 | M36: 6 | N36: 950505.17 | O36: =IF(AND($N36>='202503'!$E$2,$N36<='202503'!$F$2),'202503'!$I$2,IF(AND($N36>='202503'!$E$3,$N36<='202503'!$F$3),'202503'!$I$3,IF(AND($N36>='202503'!$E$4,$N36<='202503'!$F$4),'202503'!$I$4,IF(AND($N36>='202503'!$E$5,$N36<='202503'!$F$5),'202503'!$I$5,0)))) -> 3 | P36: =IF(AND($N36>='202503'!$E$2,$N36<='202503'!$F$2),'202503'!$G$2,IF(AND($N36>='202503'!$E$3,$N36<='202503'!$F$3),'202503'!$G$3,IF(AND($N36>='202503'!$E$4,$N36<='202503'!$F$4),'202503'!$G$4,IF(AND($N36>='202503'!$E$5,$N36<='202503'!$F$5),'202503'!$G$5,0)))) -> 4267
B37: 7662444 | C37: 76624445 | D37: 7662444-5 | E37: DELL AQUILA FUENZALIDA RODRIGO AUGUSTO | F37: 2878209 | G37: 2789699 | H37: 5193652 | I37: 2789699 | J37: 2789699 | K37: 5238125 | L37: 21679083 | M37: 6 | N37: 3613180.5 | O37: =IF(AND($N37>='202503'!$E$2,$N37<='202503'!$F$2),'202503'!$I$2,IF(AND($N37>='202503'!$E$3,$N37<='202503'!$F$3),'202503'!$I$3,IF(AND($N37>='202503'!$E$4,$N37<='202503'!$F$4),'202503'!$I$4,IF(AND($N37>='202503'!$E$5,$N37<='202503'!$F$5),'202503'!$I$5,0)))) -> 4 | P37: =IF(AND($N37>='202503'!$E$2,$N37<='202503'!$F$2),'202503'!$G$2,IF(AND($N37>='202503'!$E$3,$N37<='202503'!$F$3),'202503'!$G$3,IF(AND($N37>='202503'!$E$4,$N37<='202503'!$F$4),'202503'!$G$4,IF(AND($N37>='202503'!$E$5,$N37<='202503'!$F$5),'202503'!$G$5,0)))) -> 0
B38: 7747573 | C38: 77475737 | D38: 7747573-7 | E38: ARAVENA LAMOZA GLORIA PRISCILLA | F38: 953001 | G38: 918607 | H38: 1747252 | I38: 918607 | J38: 918607 | K38: 1754898 | L38: 7210972 | M38: 6 | N38: 1201828.7 | O38: =IF(AND($N38>='202503'!$E$2,$N38<='202503'!$F$2),'202503'!$I$2,IF(AND($N38>='202503'!$E$3,$N38<='202503'!$F$3),'202503'!$I$3,IF(AND($N38>='202503'!$E$4,$N38<='202503'!$F$4),'202503'!$I$4,IF(AND($N38>='202503'!$E$5,$N38<='202503'!$F$5),'202503'!$I$5,0)))) -> 3 | P38: =IF(AND($N38>='202503'!$E$2,$N38<='202503'!$F$2),'202503'!$G$2,IF(AND($N38>='202503'!$E$3,$N38<='202503'!$F$3),'202503'!$G$3,IF(AND($N38>='202503'!$E$4,$N38<='202503'!$F$4),'202503'!$G$4,IF(AND($N38>='202503'!$E$5,$N38<='202503'!$F$5),'202503'!$G$5,0)))) -> 4267
B39: 7772831 | C39: 77728317 | D39: 7772831-7 | E39: MUÑOZ MIRANDA GUILLERMO ANDRES | F39: 2365619 | G39: 2279165 | H39: 4332452 | I39: 2279165 | J39: 2279165 | K39: 4351418 | L39: 17886984 | M39: 6 | N39: 2981164 | O39: =IF(AND($N39>='202503'!$E$2,$N39<='202503'!$F$2),'202503'!$I$2,IF(AND($N39>='202503'!$E$3,$N39<='202503'!$F$3),'202503'!$I$3,IF(AND($N39>='202503'!$E$4,$N39<='202503'!$F$4),'202503'!$I$4,IF(AND($N39>='202503'!$E$5,$N39<='202503'!$F$5),'202503'!$I$5,0)))) -> 4 | P39: =IF(AND($N39>='202503'!$E$2,$N39<='202503'!$F$2),'202503'!$G$2,IF(AND($N39>='202503'!$E$3,$N39<='202503'!$F$3),'202503'!$G$3,IF(AND($N39>='202503'!$E$4,$N39<='202503'!$F$4),'202503'!$G$4,IF(AND($N39>='202503'!$E$5,$N39<='202503'!$F$5),'202503'!$G$5,0)))) -> 0
B40: 7797839 | C40: 77978399 | D40: 7797839-9 | E40: RUIZ ZAMORA AGUSTIN | F40: 2618383 | G40: 2537521 | H40: 4781716 | I40: 2537521 | J40: 2537521 | K40: 4802744 | L40: 19815406 | M40: 6 | N40: 3302567.7 | O40: =IF(AND($N40>='202503'!$E$2,$N40<='202503'!$F$2),'202503'!$I$2,IF(AND($N40>='202503'!$E$3,$N40<='202503'!$F$3),'202503'!$I$3,IF(AND($N40>='202503'!$E$4,$N40<='202503'!$F$4),'202503'!$I$4,IF(AND($N40>='202503'!$E$5,$N40<='202503'!$F$5),'202503'!$I$5,0)))) -> 4 | P40: =IF(AND($N40>='202503'!$E$2,$N40<='202503'!$F$2),'202503'!$G$2,IF(AND($N40>='202503'!$E$3,$N40<='202503'!$F$3),'202503'!$G$3,IF(AND($N40>='202503'!$E$4,$N40<='202503'!$F$4),'202503'!$G$4,IF(AND($N40>='202503'!$E$5,$N40<='202503'!$F$5),'202503'!$G$5,0)))) -> 0
...

Sheet Promedio 2024
D1: 1 | E1: 2 | F1: 3 | G1: 4 | H1: 5 | I1: 6 | J1: 7 | K1: 8 | L1: 9 | M1: 10 | N1: 11 | O1: 202401 | P1: 202401 | Q1: 202501 | R1: 202501 | S1: 202502 | T1: 202502
B2: 1 | C2: rut | D2: RUT | E2: nombre_beneficiario | F2: enero | G2: febrero | H2: marzo | I2: abril | J2: mayo | K2: junio | L2: total | M2: meses | N2: Promedio | O2: tramo | P2: valor | Q2: tramo | R2: valor | S2: tramo | T2: valor
B3: 13723213 | C3: 137232138 | D3: 13723213-8 | E3: ZURITA VERA ALEJANDRA ANDREA | F3: 832772 | G3: 832772 | H3: 1776978 | I3: 836714 | J3: 836714 | K3: 1716465 | L3: =SUM(F3:K3) -> 6832415 | M3: 6 | N3: 1138735 | O3: =IF(AND($N3>='202401'!$E$2,$N3<='202401'!$F$2),'202401'!$I$2,IF(AND($N3>='202401'!$E$3,$N3<='202401'!$F$3),'202401'!$I$3,IF(AND($N3>='202401'!$E$4,$N3<='202401'!$F$4),'202401'!$I$4,IF(AND($N3>='202401'!$E$5,$N3<='202401'!$F$5),'202401'!$I$5,0)))) -> 3 | P3: =IF(AND($N3>='202401'!$E$2,$N3<='202401'!$F$2),'202401'!$G$2,IF(AND($N3>='202401'!$E$3,$N3<='202401'!$F$3),'202401'!$G$3,IF(AND($N3>='202401'!$E$4,$N3<='202401'!$F$4),'202401'!$G$4,IF(AND($N3>='202401'!$E$5,$N3<='202401'!$F$5),'202401'!$G$5,0)))) -> 4119 | Q3: =IF(AND($N3>='202501'!$E$2,$N3<='202501'!$F$2),'202501'!$I$2,IF(AND($N3>='202501'!$E$3,$N3<='202501'!$F$3),'202501'!$I$3,IF(AND($N3>='202501'!$E$4,$N3<='202501'!$F$4),'202501'!$I$4,IF(AND($N3>='202501'!$E$5,$N3<='202501'!$F$5),'202501'!$I$5,0)))) -> 3 | R3: =IF(AND($N3>='202501'!$E$2,$N3<='202501'!$F$2),'202501'!$G$2,IF(AND($N3>='202501'!$E$3,$N3<='202501'!$F$3),'202501'!$G$3,IF(AND($N3>='202501'!$E$4,$N3<='202501'!$F$4),'202501'!$G$4,IF(AND($N3>='202501'!$E$5,$N3<='202501'!$F$5),'202501'!$G$5,0)))) -> 4119 | S3: =IF(AND($N3>='202502'!$E$2,$N3<='202502'!$F$2),'202502'!$I$2,IF(AND($N3>='202502'!$E$3,$N3<='202502'!$F$3),'202502'!$I$3,IF(AND($N3>='202502'!$E$4,$N3<='202502'!$F$4),'202502'!$I$4,IF(AND($N3>='202502'!$E$5,$N3<='202502'!$F$5),'202502'!$I$5,0)))) -> 3 | T3: =IF(AND($N3>='202502'!$E$2,$N3<='202502'!$F$2),'202502'!$G$2,IF(AND($N3>='202502'!$E$3,$N3<='202502'!$F$3),'202502'!$G$3,IF(AND($N3>='202502'!$E$4,$N3<='202502'!$F$4),'202502'!$G$4,IF(AND($N3>='202502'!$E$5,$N3<='202502'!$F$5),'202502'!$G$5,0)))) -> 4267
B4: 12388357 | C4: 123883578 | D4: 12388357-8 | E4: ZUÑIGA SAN MARTIN CESAR DONALDO | F4: 1072699 | G4: 903229 | H4: 1694761 | I4: 953130 | J4: 976669 | K4: 1774977 | L4: =SUM(F4:K4) -> 7375465 | M4: 6 | N4: 1229244 | O4: =IF(AND($N4>='202401'!$E$2,$N4<='202401'!$F$2),'202401'!$I$2,IF(AND($N4>='202401'!$E$3,$N4<='202401'!$F$3),'202401'!$I$3,IF(AND($N4>='202401'!$E$4,$N4<='202401'!$F$4),'202401'!$I$4,IF(AND($N4>='202401'!$E$5,$N4<='202401'!$F$5),'202401'!$I$5,0)))) -> 3 | P4: =IF(AND($N4>='202401'!$E$2,$N4<='202401'!$F$2),'202401'!$G$2,IF(AND($N4>='202401'!$E$3,$N4<='202401'!$F$3),'202401'!$G$3,IF(AND($N4>='202401'!$E$4,$N4<='202401'!$F$4),'202401'!$G$4,IF(AND($N4>='202401'!$E$5,$N4<='202401'!$F$5),'202401'!$G$5,0)))) -> 4119 | Q4: =IF(AND($N4>='202501'!$E$2,$N4<='202501'!$F$2),'202501'!$I$2,IF(AND($N4>='202501'!$E$3,$N4<='202501'!$F$3),'202501'!$I$3,IF(AND($N4>='202501'!$E$4,$N4<='202501'!$F$4),'202501'!$I$4,IF(AND($N4>='202501'!$E$5,$N4<='202501'!$F$5),'202501'!$I$5,0)))) -> 3 | R4: =IF(AND($N4>='202501'!$E$2,$N4<='202501'!$F$2),'202501'!$G$2,IF(AND($N4>='202501'!$E$3,$N4<='202501'!$F$3),'202501'!$G$3,IF(AND($N4>='202501'!$E$4,$N4<='202501'!$F$4),'202501'!$G$4,IF(AND($N4>='202501'!$E$5,$N4<='202501'!$F$5),'202501'!$G$5,0)))) -> 4119 | S4: =IF(AND($N4>='202502'!$E$2,$N4<='202502'!$F$2),'202502'!$I$2,IF(AND($N4>='202502'!$E$3,$N4<='202502'!$F$3),'202502'!$I$3,IF(AND($N4>='202502'!$E$4,$N4<='202502'!$F$4),'202502'!$I$4,IF(AND($N4>='202502'!$E$5,$N4<='202502'!$F$5),'202502'!$I$5,0)))) -> 3 | T4: =IF(AND($N4>='202502'!$E$2,$N4<='202502'!$F$2),'202502'!$G$2,IF(AND($N4>='202502'!$E$3,$N4<='202502'!$F$3),'202502'!$G$3,IF(AND($N4>='202502'!$E$4,$N4<='202502'!$F$4),'202502'!$G$4,IF(AND($N4>='202502'!$E$5,$N4<='202502'!$F$5),'202502'!$G$5,0)))) -> 4267
B5: 8792255 | C5: 87922553 | D5: 8792255-3 | E5: ZUÑIGA RODRIGUEZ CONRADO | F5: 2188124 | G5: 2188124 | H5: 3815778 | I5: 2188124 | J5: 2552214 | K5: 3829432 | L5: =SUM(F5:K5) -> 16761796 | M5: 6 | N5: 2793632 | O5: =IF(AND($N5>='202401'!$E$2,$N5<='202401'!$F$2),'202401'!$I$2,IF(AND($N5>='202401'!$E$3,$N5<='202401'!$F$3),'202401'!$I$3,IF(AND($N5>='202401'!$E$4,$N5<='202401'!$F$4),'202401'!$I$4,IF(AND($N5>='202401'!$E$5,$N5<='202401'!$F$5),'202401'!$I$5,0)))) -> 4 | P5: =IF(AND($N5>='202401'!$E$2,$N5<='202401'!$F$2),'202401'!$G$2,IF(AND($N5>='202401'!$E$3,$N5<='202401'!$F$3),'202401'!$G$3,IF(AND($N5>='202401'!$E$4,$N5<='202401'!$F$4),'202401'!$G$4,IF(AND($N5>='202401'!$E$5,$N5<='202401'!$F$5),'202401'!$G$5,0)))) -> 0 | Q5: =IF(AND($N5>='202501'!$E$2,$N5<='202501'!$F$2),'202501'!$I$2,IF(AND($N5>='202501'!$E$3,$N5<='202501'!$F$3),'202501'!$I$3,IF(AND($N5>='202501'!$E$4,$N5<='202501'!$F$4),'202501'!$I$4,IF(AND($N5>='202501'!$E$5,$N5<='202501'!$F$5),'202501'!$I$5,0)))) -> 4 | R5: =IF(AND($N5>='202501'!$E$2,$N5<='202501'!$F$2),'202501'!$G$2,IF(AND($N5>='202501'!$E$3,$N5<='202501'!$F$3),'202501'!$G$3,IF(AND($N5>='202501'!$E$4,$N5<='202501'!$F$4),'202501'!$G$4,IF(AND($N5>='202501'!$E$5,$N5<='202501'!$F$5),'202501'!$G$5,0)))) -> 0 | S5: =IF(AND($N5>='202502'!$E$2,$N5<='202502'!$F$2),'202502'!$I$2,IF(AND($N5>='202502'!$E$3,$N5<='202502'!$F$3),'202502'!$I$3,IF(AND($N5>='202502'!$E$4,$N5<='202502'!$F$4),'202502'!$I$4,IF(AND($N5>='202502'!$E$5,$N5<='202502'!$F$5),'202502'!$I$5,0)))) -> 4 | T5: =IF(AND($N5>='202502'!$E$2,$N5<='202502'!$F$2),'202502'!$G$2,IF(AND($N5>='202502'!$E$3,$N5<='202502'!$F$3),'202502'!$G$3,IF(AND($N5>='202502'!$E$4,$N5<='202502'!$F$4),'202502'!$G$4,IF(AND($N5>='202502'!$E$5,$N5<='202502'!$F$5),'202502'!$G$5,0)))) -> 0
B6: 13230664 | C6: 132306648 | D6: 13230664-8 | E6: ZUÑIGA LUCERO CRISTIAN ANDRES | F6: 2566908 | G6: 2566908 | H6: 4838948 | I6: 2566908 | J6: 2566908 | K6: 4879854 | L6: =SUM(F6:K6) -> 19986434 | M6: 6 | N6: 3331072 | O6: =IF(AND($N6>='202401'!$E$2,$N6<='202401'!$F$2),'202401'!$I$2,IF(AND($N6>='202401'!$E$3,$N6<='202401'!$F$3),'202401'!$I$3,IF(AND($N6>='202401'!$E$4,$N6<='202401'!$F$4),'202401'!$I$4,IF(AND($N6>='202401'!$E$5,$N6<='202401'!$F$5),'202401'!$I$5,0)))) -> 4 | P6: =IF(AND($N6>='202401'!$E$2,$N6<='202401'!$F$2),'202401'!$G$2,IF(AND($N6>='202401'!$E$3,$N6<='202401'!$F$3),'202401'!$G$3,IF(AND($N6>='202401'!$E$4,$N6<='202401'!$F$4),'202401'!$G$4,IF(AND($N6>='202401'!$E$5,$N6<='202401'!$F$5),'202401'!$G$5,0)))) -> 0 | Q6: =IF(AND($N6>='202501'!$E$2,$N6<='202501'!$F$2),'202501'!$I$2,IF(AND($N6>='202501'!$E$3,$N6<='202501'!$F$3),'202501'!$I$3,IF(AND($N6>='202501'!$E$4,$N6<='202501'!$F$4),'202501'!$I$4,IF(AND($N6>='202501'!$E$5,$N6<='202501'!$F$5),'202501'!$I$5,0)))) -> 4 | R6: =IF(AND($N6>='202501'!$E$2,$N6<='202501'!$F$2),'202501'!$G$2,IF(AND($N6>='202501'!$E$3,$N6<='202501'!$F$3),'202501'!$G$3,IF(AND($N6>='202501'!$E$4,$N6<='202501'!$F$4),'202501'!$G$4,IF(AND($N6>='202501'!$E$5,$N6<='202501'!$F$5),'202501'!$G$5,0)))) -> 0 | S6: =IF(AND($N6>='202502'!$E$2,$N6<='202502'!$F$2),'202502'!$I$2,IF(AND($N6>='202502'!$E$3,$N6<='202502'!$F$3),'202502'!$I$3,IF(AND($N6>='202502'!$E$4,$N6<='202502'!$F$4),'202502'!$I$4,IF(AND($N6>='202502'!$E$5,$N6<='202502'!$F$5),'202502'!$I$5,0)))) -> 4 | T6: =IF(AND($N6>='202502'!$E$2,$N6<='202502'!$F$2),'202502'!$G$2,IF(AND($N6>='202502'!$E$3,$N6<='202502'!$F$3),'202502'!$G$3,IF(AND($N6>='202502'!$E$4,$N6<='202502'!$F$4),'202502'!$G$4,IF(AND($N6>='202502'!$E$5,$N6<='202502'!$F$5),'202502'!$G$5,0)))) -> 0
B7: 16122931 | C7: 161229318 | D7: 16122931-8 | E7: ZUÑIGA HERRERA MONICA PAZ | F7: 1169535 | G7: 1169535 | H7: 2242689 | I7: 1169535 | J7: 1169535 | K7: 2250325 | L7: =SUM(F7:K7) -> 9171154 | M7: 6 | N7: 1528525 | O7: =IF(AND($N7>='202401'!$E$2,$N7<='202401'!$F$2),'202401'!$I$2,IF(AND($N7>='202401'!$E$3,$N7<='202401'!$F$3),'202401'!$I$3,IF(AND($N7>='202401'!$E$4,$N7<='202401'!$F$4),'202401'!$I$4,IF(AND($N7>='202401'!$E$5,$N7<='202401'!$F$5),'202401'!$I$5,0)))) -> 4 | P7: =IF(AND($N7>='202401'!$E$2,$N7<='202401'!$F$2),'202401'!$G$2,IF(AND($N7>='202401'!$E$3,$N7<='202401'!$F$3),'202401'!$G$3,IF(AND($N7>='202401'!$E$4,$N7<='202401'!$F$4),'202401'!$G$4,IF(AND($N7>='202401'!$E$5,$N7<='202401'!$F$5),'202401'!$G$5,0)))) -> 0 | Q7: =IF(AND($N7>='202501'!$E$2,$N7<='202501'!$F$2),'202501'!$I$2,IF(AND($N7>='202501'!$E$3,$N7<='202501'!$F$3),'202501'!$I$3,IF(AND($N7>='202501'!$E$4,$N7<='202501'!$F$4),'202501'!$I$4,IF(AND($N7>='202501'!$E$5,$N7<='202501'!$F$5),'202501'!$I$5,0)))) -> 4 | R7: =IF(AND($N7>='202501'!$E$2,$N7<='202501'!$F$2),'202501'!$G$2,IF(AND($N7>='202501'!$E$3,$N7<='202501'!$F$3),'202501'!$G$3,IF(AND($N7>='202501'!$E$4,$N7<='202501'!$F$4),'202501'!$G$4,IF(AND($N7>='202501'!$E$5,$N7<='202501'!$F$5),'202501'!$G$5,0)))) -> 0 | S7: =IF(AND($N7>='202502'!$E$2,$N7<='202502'!$F$2),'202502'!$I$2,IF(AND($N7>='202502'!$E$3,$N7<='202502'!$F$3),'202502'!$I$3,IF(AND($N7>='202502'!$E$4,$N7<='202502'!$F$4),'202502'!$I$4,IF(AND($N7>='202502'!$E$5,$N7<='202502'!$F$5),'202502'!$I$5,0)))) -> 4 | T7: =IF(AND($N7>='202502'!$E$2,$N7<='202502'!$F$2),'202502'!$G$2,IF(AND($N7>='202502'!$E$3,$N7<='202502'!$F$3),'202502'!$G$3,IF(AND($N7>='202502'!$E$4,$N7<='202502'!$F$4),'202502'!$G$4,IF(AND($N7>='202502'!$E$5,$N7<='202502'!$F$5),'202502'!$G$5,0)))) -> 0
B8: 14081052 | C8: 140810525 | D8: 14081052-5 | E8: ZUÑIGA GONZALEZ KATHERINE | F8: 1046568 | G8: 1018535 | H8: 1898111 | I8: 1018535 | J8: 1018535 | K8: 1904668 | L8: =SUM(F8:K8) -> 7904952 | M8: 6 | N8: 1317492 | O8: =IF(AND($N8>='202401'!$E$2,$N8<='202401'!$F$2),'202401'!$I$2,IF(AND($N8>='202401'!$E$3,$N8<='202401'!$F$3),'202401'!$I$3,IF(AND($N8>='202401'!$E$4,$N8<='202401'!$F$4),'202401'!$I$4,IF(AND($N8>='202401'!$E$5,$N8<='202401'!$F$5),'202401'!$I$5,0)))) -> 3 | P8: =IF(AND($N8>='202401'!$E$2,$N8<='202401'!$F$2),'202401'!$G$2,IF(AND($N8>='202401'!$E$3,$N8<='202401'!$F$3),'202401'!$G$3,IF(AND($N8>='202401'!$E$4,$N8<='202401'!$F$4),'202401'!$G$4,IF(AND($N8>='202401'!$E$5,$N8<='202401'!$F$5),'202401'!$G$5,0)))) -> 4119 | Q8: =IF(AND($N8>='202501'!$E$2,$N8<='202501'!$F$2),'202501'!$I$2,IF(AND($N8>='202501'!$E$3,$N8<='202501'!$F$3),'202501'!$I$3,IF(AND($N8>='202501'!$E$4,$N8<='202501'!$F$4),'202501'!$I$4,IF(AND($N8>='202501'!$E$5,$N8<='202501'!$F$5),'202501'!$I$5,0)))) -> 3 | R8: =IF(AND($N8>='202501'!$E$2,$N8<='202501'!$F$2),'202501'!$G$2,IF(AND($N8>='202501'!$E$3,$N8<='202501'!$F$3),'202501'!$G$3,IF(AND($N8>='202501'!$E$4,$N8<='202501'!$F$4),'202501'!$G$4,IF(AND($N8>='202501'!$E$5,$N8<='202501'!$F$5),'202501'!$G$5,0)))) -> 4119 | S8: =IF(AND($N8>='202502'!$E$2,$N8<='202502'!$F$2),'202502'!$I$2,IF(AND($N8>='202502'!$E$3,$N8<='202502'!$F$3),'202502'!$I$3,IF(AND($N8>='202502'!$E$4,$N8<='202502'!$F$4),'202502'!$I$4,IF(AND($N8>='202502'!$E$5,$N8<='202502'!$F$5),'202502'!$I$5,0)))) -> 3 | T8: =IF(AND($N8>='202502'!$E$2,$N8<='202502'!$F$2),'202502'!$G$2,IF(AND($N8>='202502'!$E$3,$N8<='202502'!$F$3),'202502'!$G$3,IF(AND($N8>='202502'!$E$4,$N8<='202502'!$F$4),'202502'!$G$4,IF(AND($N8>='202502'!$E$5,$N8<='202502'!$F$5),'202502'!$G$5,0)))) -> 4267
B9: 18489749 | C9: 184897490 | D9: 18489749-0 | E9: ZUÑIGA FRITZ ROLY FRANCISCO | F9: 802819 | G9: 802819 | H9: 1512208 | I9: 802819 | J9: 802819 | K9: 1517404 | L9: =SUM(F9:K9) -> 6240888 | M9: 6 | N9: 1040148 | O9: =IF(AND($N9>='202401'!$E$2,$N9<='202401'!$F$2),'202401'!$I$2,IF(AND($N9>='202401'!$E$3,$N9<='202401'!$F$3),'202401'!$I$3,IF(AND($N9>='202401'!$E$4,$N9<='202401'!$F$4),'202401'!$I$4,IF(AND($N9>='202401'!$E$5,$N9<='202401'!$F$5),'202401'!$I$5,0)))) -> 3 | P9: =IF(AND($N9>='202401'!$E$2,$N9<='202401'!$F$2),'202401'!$G$2,IF(AND($N9>='202401'!$E$3,$N9<='202401'!$F$3),'202401'!$G$3,IF(AND($N9>='202401'!$E$4,$N9<='202401'!$F$4),'202401'!$G$4,IF(AND($N9>='202401'!$E$5,$N9<='202401'!$F$5),'202401'!$G$5,0)))) -> 4119 | Q9: =IF(AND($N9>='202501'!$E$2,$N9<='202501'!$F$2),'202501'!$I$2,IF(AND($N9>='202501'!$E$3,$N9<='202501'!$F$3),'202501'!$I$3,IF(AND($N9>='202501'!$E$4,$N9<='202501'!$F$4),'202501'!$I$4,IF(AND($N9>='202501'!$E$5,$N9<='202501'!$F$5),'202501'!$I$5,0)))) -> 3 | R9: =IF(AND($N9>='202501'!$E$2,$N9<='202501'!$F$2),'202501'!$G$2,IF(AND($N9>='202501'!$E$3,$N9<='202501'!$F$3),'202501'!$G$3,IF(AND($N9>='202501'!$E$4,$N9<='202501'!$F$4),'202501'!$G$4,IF(AND($N9>='202501'!$E$5,$N9<='202501'!$F$5),'202501'!$G$5,0)))) -> 4119 | S9: =IF(AND($N9>='202502'!$E$2,$N9<='202502'!$F$2),'202502'!$I$2,IF(AND($N9>='202502'!$E$3,$N9<='202502'!$F$3),'202502'!$I$3,IF(AND($N9>='202502'!$E$4,$N9<='202502'!$F$4),'202502'!$I$4,IF(AND($N9>='202502'!$E$5,$N9<='202502'!$F$5),'202502'!$I$5,0)))) -> 3 | T9: =IF(AND($N9>='202502'!$E$2,$N9<='202502'!$F$2),'202502'!$G$2,IF(AND($N9>='202502'!$E$3,$N9<='202502'!$F$3),'202502'!$G$3,IF(AND($N9>='202502'!$E$4,$N9<='202502'!$F$4),'202502'!$G$4,IF(AND($N9>='202502'!$E$5,$N9<='202502'!$F$5),'202502'!$G$5,0)))) -> 4267
B10: 15805886 | C10: 158058863 | D10: 15805886-3 | E10: ZUÑIGA CHANDIA ANTONIO IGNACIO | F10: 2163893 | G10: 2163893 | H10: 4125212 | I10: 2163893 | J10: 2163893 | K10: 4139303 | L10: =SUM(F10:K10) -> 16920087 | M10: 6 | N10: 2820014 | O10: =IF(AND($N10>='202401'!$E$2,$N10<='202401'!$F$2),'202401'!$I$2,IF(AND($N10>='202401'!$E$3,$N10<='202401'!$F$3),'202401'!$I$3,IF(AND($N10>='202401'!$E$4,$N10<='202401'!$F$4),'202401'!$I$4,IF(AND($N10>='202401'!$E$5,$N10<='202401'!$F$5),'202401'!$I$5,0)))) -> 4 | P10: =IF(AND($N10>='202401'!$E$2,$N10<='202401'!$F$2),'202401'!$G$2,IF(AND($N10>='202401'!$E$3,$N10<='202401'!$F$3),'202401'!$G$3,IF(AND($N10>='202401'!$E$4,$N10<='202401'!$F$4),'202401'!$G$4,IF(AND($N10>='202401'!$E$5,$N10<='202401'!$F$5),'202401'!$G$5,0)))) -> 0 | Q10: =IF(AND($N10>='202501'!$E$2,$N10<='202501'!$F$2),'202501'!$I$2,IF(AND($N10>='202501'!$E$3,$N10<='202501'!$F$3),'202501'!$I$3,IF(AND($N10>='202501'!$E$4,$N10<='202501'!$F$4),'202501'!$I$4,IF(AND($N10>='202501'!$E$5,$N10<='202501'!$F$5),'202501'!$I$5,0)))) -> 4 | R10: =IF(AND($N10>='202501'!$E$2,$N10<='202501'!$F$2),'202501'!$G$2,IF(AND($N10>='202501'!$E$3,$N10<='202501'!$F$3),'202501'!$G$3,IF(AND($N10>='202501'!$E$4,$N10<='202501'!$F$4),'202501'!$G$4,IF(AND($N10>='202501'!$E$5,$N10<='202501'!$F$5),'202501'!$G$5,0)))) -> 0 | S10: =IF(AND($N10>='202502'!$E$2,$N10<='202502'!$F$2),'202502'!$I$2,IF(AND($N10>='202502'!$E$3,$N10<='202502'!$F$3),'202502'!$I$3,IF(AND($N10>='202502'!$E$4,$N10<='202502'!$F$4),'202502'!$I$4,IF(AND($N10>='202502'!$E$5,$N10<='202502'!$F$5),'202502'!$I$5,0)))) -> 4 | T10: =IF(AND($N10>='202502'!$E$2,$N10<='202502'!$F$2),'202502'!$G$2,IF(AND($N10>='202502'!$E$3,$N10<='202502'!$F$3),'202502'!$G$3,IF(AND($N10>='202502'!$E$4,$N10<='202502'!$F$4),'202502'!$G$4,IF(AND($N10>='202502'!$E$5,$N10<='202502'!$F$5),'202502'!$G$5,0)))) -> 0
B11: 17516540 | C11: 175165401 | D11: 17516540-1 | E11: ZUÑIGA CERDA PALOMA IGNACIA | J11: 5153591 | K11: 4690042 | L11: =SUM(F11:K11) -> 9843633 | M11: 2 | N11: 4921816 | O11: =IF(AND($N11>='202401'!$E$2,$N11<='202401'!$F$2),'202401'!$I$2,IF(AND($N11>='202401'!$E$3,$N11<='202401'!$F$3),'202401'!$I$3,IF(AND($N11>='202401'!$E$4,$N11<='202401'!$F$4),'202401'!$I$4,IF(AND($N11>='202401'!$E$5,$N11<='202401'!$F$5),'202401'!$I$5,0)))) -> 4 | P11: =IF(AND($N11>='202401'!$E$2,$N11<='202401'!$F$2),'202401'!$G$2,IF(AND($N11>='202401'!$E$3,$N11<='202401'!$F$3),'202401'!$G$3,IF(AND($N11>='202401'!$E$4,$N11<='202401'!$F$4),'202401'!$G$4,IF(AND($N11>='202401'!$E$5,$N11<='202401'!$F$5),'202401'!$G$5,0)))) -> 0 | Q11: =IF(AND($N11>='202501'!$E$2,$N11<='202501'!$F$2),'202501'!$I$2,IF(AND($N11>='202501'!$E$3,$N11<='202501'!$F$3),'202501'!$I$3,IF(AND($N11>='202501'!$E$4,$N11<='202501'!$F$4),'202501'!$I$4,IF(AND($N11>='202501'!$E$5,$N11<='202501'!$F$5),'202501'!$I$5,0)))) -> 4 | R11: =IF(AND($N11>='202501'!$E$2,$N11<='202501'!$F$2),'202501'!$G$2,IF(AND($N11>='202501'!$E$3,$N11<='202501'!$F$3),'202501'!$G$3,IF(AND($N11>='202501'!$E$4,$N11<='202501'!$F$4),'202501'!$G$4,IF(AND($N11>='202501'!$E$5,$N11<='202501'!$F$5),'202501'!$G$5,0)))) -> 0 | S11: =IF(AND($N11>='202502'!$E$2,$N11<='202502'!$F$2),'202502'!$I$2,IF(AND($N11>='202502'!$E$3,$N11<='202502'!$F$3),'202502'!$I$3,IF(AND($N11>='202502'!$E$4,$N11<='202502'!$F$4),'202502'!$I$4,IF(AND($N11>='202502'!$E$5,$N11<='202502'!$F$5),'202502'!$I$5,0)))) -> 4 | T11: =IF(AND($N11>='202502'!$E$2,$N11<='202502'!$F$2),'202502'!$G$2,IF(AND($N11>='202502'!$E$3,$N11<='202502'!$F$3),'202502'!$G$3,IF(AND($N11>='202502'!$E$4,$N11<='202502'!$F$4),'202502'!$G$4,IF(AND($N11>='202502'!$E$5,$N11<='202502'!$F$5),'202502'!$G$5,0)))) -> 0
B12: 11637149 | C12: 116371499 | D12: 11637149-9 | E12: ZUÑIGA BAEZA MONICA DEL ROSARIO | F12: 1863659 | G12: 1863659 | H12: 3487550 | I12: 1863659 | J12: 1863659 | K12: 3499576 | L12: =SUM(F12:K12) -> 14441762 | M12: 6 | N12: 2406960 | O12: =IF(AND($N12>='202401'!$E$2,$N12<='202401'!$F$2),'202401'!$I$2,IF(AND($N12>='202401'!$E$3,$N12<='202401'!$F$3),'202401'!$I$3,IF(AND($N12>='202401'!$E$4,$N12<='202401'!$F$4),'202401'!$I$4,IF(AND($N12>='202401'!$E$5,$N12<='202401'!$F$5),'202401'!$I$5,0)))) -> 4 | P12: =IF(AND($N12>='202401'!$E$2,$N12<='202401'!$F$2),'202401'!$G$2,IF(AND($N12>='202401'!$E$3,$N12<='202401'!$F$3),'202401'!$G$3,IF(AND($N12>='202401'!$E$4,$N12<='202401'!$F$4),'202401'!$G$4,IF(AND($N12>='202401'!$E$5,$N12<='202401'!$F$5),'202401'!$G$5,0)))) -> 0 | Q12: =IF(AND($N12>='202501'!$E$2,$N12<='202501'!$F$2),'202501'!$I$2,IF(AND($N12>='202501'!$E$3,$N12<='202501'!$F$3),'202501'!$I$3,IF(AND($N12>='202501'!$E$4,$N12<='202501'!$F$4),'202501'!$I$4,IF(AND($N12>='202501'!$E$5,$N12<='202501'!$F$5),'202501'!$I$5,0)))) -> 4 | R12: =IF(AND($N12>='202501'!$E$2,$N12<='202501'!$F$2),'202501'!$G$2,IF(AND($N12>='202501'!$E$3,$N12<='202501'!$F$3),'202501'!$G$3,IF(AND($N12>='202501'!$E$4,$N12<='202501'!$F$4),'202501'!$G$4,IF(AND($N12>='202501'!$E$5,$N12<='202501'!$F$5),'202501'!$G$5,0)))) -> 0 | S12: =IF(AND($N12>='202502'!$E$2,$N12<='202502'!$F$2),'202502'!$I$2,IF(AND($N12>='202502'!$E$3,$N12<='202502'!$F$3),'202502'!$I$3,IF(AND($N12>='202502'!$E$4,$N12<='202502'!$F$4),'202502'!$I$4,IF(AND($N12>='202502'!$E$5,$N12<='202502'!$F$5),'202502'!$I$5,0)))) -> 4 | T12: =IF(AND($N12>='202502'!$E$2,$N12<='202502'!$F$2),'202502'!$G$2,IF(AND($N12>='202502'!$E$3,$N12<='202502'!$F$3),'202502'!$G$3,IF(AND($N12>='202502'!$E$4,$N12<='202502'!$F$4),'202502'!$G$4,IF(AND($N12>='202502'!$E$5,$N12<='202502'!$F$5),'202502'!$G$5,0)))) -> 0
B13: 15032811 | C13: 15032811K | D13: 15032811-K | E13: ZUMARAN ADARO NICOLAS BERNARDO | F13: 805965 | G13: 805965 | H13: 1479639 | I13: 805965 | J13: 805965 | K13: 1484791 | L13: =SUM(F13:K13) -> 6188290 | M13: 6 | N13: 1031381 | O13: =IF(AND($N13>='202401'!$E$2,$N13<='202401'!$F$2),'202401'!$I$2,IF(AND($N13>='202401'!$E$3,$N13<='202401'!$F$3),'202401'!$I$3,IF(AND($N13>='202401'!$E$4,$N13<='202401'!$F$4),'202401'!$I$4,IF(AND($N13>='202401'!$E$5,$N13<='202401'!$F$5),'202401'!$I$5,0)))) -> 3 | P13: =IF(AND($N13>='202401'!$E$2,$N13<='202401'!$F$2),'202401'!$G$2,IF(AND($N13>='202401'!$E$3,$N13<='202401'!$F$3),'202401'!$G$3,IF(AND($N13>='202401'!$E$4,$N13<='202401'!$F$4),'202401'!$G$4,IF(AND($N13>='202401'!$E$5,$N13<='202401'!$F$5),'202401'!$G$5,0)))) -> 4119 | Q13: =IF(AND($N13>='202501'!$E$2,$N13<='202501'!$F$2),'202501'!$I$2,IF(AND($N13>='202501'!$E$3,$N13<='202501'!$F$3),'202501'!$I$3,IF(AND($N13>='202501'!$E$4,$N13<='202501'!$F$4),'202501'!$I$4,IF(AND($N13>='202501'!$E$5,$N13<='202501'!$F$5),'202501'!$I$5,0)))) -> 3 | R13: =IF(AND($N13>='202501'!$E$2,$N13<='202501'!$F$2),'202501'!$G$2,IF(AND($N13>='202501'!$E$3,$N13<='202501'!$F$3),'202501'!$G$3,IF(AND($N13>='202501'!$E$4,$N13<='202501'!$F$4),'202501'!$G$4,IF(AND($N13>='202501'!$E$5,$N13<='202501'!$F$5),'202501'!$G$5,0)))) -> 4119 | S13: =IF(AND($N13>='202502'!$E$2,$N13<='202502'!$F$2),'202502'!$I$2,IF(AND($N13>='202502'!$E$3,$N13<='202502'!$F$3),'202502'!$I$3,IF(AND($N13>='202502'!$E$4,$N13<='202502'!$F$4),'202502'!$I$4,IF(AND($N13>='202502'!$E$5,$N13<='202502'!$F$5),'202502'!$I$5,0)))) -> 3 | T13: =IF(AND($N13>='202502'!$E$2,$N13<='202502'!$F$2),'202502'!$G$2,IF(AND($N13>='202502'!$E$3,$N13<='202502'!$F$3),'202502'!$G$3,IF(AND($N13>='202502'!$E$4,$N13<='202502'!$F$4),'202502'!$G$4,IF(AND($N13>='202502'!$E$5,$N13<='202502'!$F$5),'202502'!$G$5,0)))) -> 4267
B14: 13548200 | C14: 135482005 | D14: 13548200-5 | E14: ZSCHOCHE VALLE ROSARIO PAZ | F14: 3072176 | G14: 3072176 | H14: 5381438 | I14: 3072176 | J14: 3072176 | K14: 5484123 | L14: =SUM(F14:K14) -> 23154265 | M14: 6 | N14: 3859044 | O14: =IF(AND($N14>='202401'!$E$2,$N14<='202401'!$F$2),'202401'!$I$2,IF(AND($N14>='202401'!$E$3,$N14<='202401'!$F$3),'202401'!$I$3,IF(AND($N14>='202401'!$E$4,$N14<='202401'!$F$4),'202401'!$I$4,IF(AND($N14>='202401'!$E$5,$N14<='202401'!$F$5),'202401'!$I$5,0)))) -> 4 | P14: =IF(AND($N14>='202401'!$E$2,$N14<='202401'!$F$2),'202401'!$G$2,IF(AND($N14>='202401'!$E$3,$N14<='202401'!$F$3),'202401'!$G$3,IF(AND($N14>='202401'!$E$4,$N14<='202401'!$F$4),'202401'!$G$4,IF(AND($N14>='202401'!$E$5,$N14<='202401'!$F$5),'202401'!$G$5,0)))) -> 0 | Q14: =IF(AND($N14>='202501'!$E$2,$N14<='202501'!$F$2),'202501'!$I$2,IF(AND($N14>='202501'!$E$3,$N14<='202501'!$F$3),'202501'!$I$3,IF(AND($N14>='202501'!$E$4,$N14<='202501'!$F$4),'202501'!$I$4,IF(AND($N14>='202501'!$E$5,$N14<='202501'!$F$5),'202501'!$I$5,0)))) -> 4 | R14: =IF(AND($N14>='202501'!$E$2,$N14<='202501'!$F$2),'202501'!$G$2,IF(AND($N14>='202501'!$E$3,$N14<='202501'!$F$3),'202501'!$G$3,IF(AND($N14>='202501'!$E$4,$N14<='202501'!$F$4),'202501'!$G$4,IF(AND($N14>='202501'!$E$5,$N14<='202501'!$F$5),'202501'!$G$5,0)))) -> 0 | S14: =IF(AND($N14>='202502'!$E$2,$N14<='202502'!$F$2),'202502'!$I$2,IF(AND($N14>='202502'!$E$3,$N14<='202502'!$F$3),'202502'!$I$3,IF(AND($N14>='202502'!$E$4,$N14<='202502'!$F$4),'202502'!$I$4,IF(AND($N14>='202502'!$E$5,$N14<='202502'!$F$5),'202502'!$I$5,0)))) -> 4 | T14: =IF(AND($N14>='202502'!$E$2,$N14<='202502'!$F$2),'202502'!$G$2,IF(AND($N14>='202502'!$E$3,$N14<='202502'!$F$3),'202502'!$G$3,IF(AND($N14>='202502'!$E$4,$N14<='202502'!$F$4),'202502'!$G$4,IF(AND($N14>='202502'!$E$5,$N14<='202502'!$F$5),'202502'!$G$5,0)))) -> 0
B15: 16886314 | C15: 168863144 | D15: 16886314-4 | E15: ZEPEDA NAVARRO FRANCISCO JAVIER | F15: 2140352 | G15: 2140352 | H15: 3962582 | I15: 2140352 | J15: 2140352 | K15: 3976323 | L15: =SUM(F15:K15) -> 16500313 | M15: 6 | N15: 2750052 | O15: =IF(AND($N15>='202401'!$E$2,$N15<='202401'!$F$2),'202401'!$I$2,IF(AND($N15>='202401'!$E$3,$N15<='202401'!$F$3),'202401'!$I$3,IF(AND($N15>='202401'!$E$4,$N15<='202401'!$F$4),'202401'!$I$4,IF(AND($N15>='202401'!$E$5,$N15<='202401'!$F$5),'202401'!$I$5,0)))) -> 4 | P15: =IF(AND($N15>='202401'!$E$2,$N15<='202401'!$F$2),'202401'!$G$2,IF(AND($N15>='202401'!$E$3,$N15<='202401'!$F$3),'202401'!$G$3,IF(AND($N15>='202401'!$E$4,$N15<='202401'!$F$4),'202401'!$G$4,IF(AND($N15>='202401'!$E$5,$N15<='202401'!$F$5),'202401'!$G$5,0)))) -> 0 | Q15: =IF(AND($N15>='202501'!$E$2,$N15<='202501'!$F$2),'202501'!$I$2,IF(AND($N15>='202501'!$E$3,$N15<='202501'!$F$3),'202501'!$I$3,IF(AND($N15>='202501'!$E$4,$N15<='202501'!$F$4),'202501'!$I$4,IF(AND($N15>='202501'!$E$5,$N15<='202501'!$F$5),'202501'!$I$5,0)))) -> 4 | R15: =IF(AND($N15>='202501'!$E$2,$N15<='202501'!$F$2),'202501'!$G$2,IF(AND($N15>='202501'!$E$3,$N15<='202501'!$F$3),'202501'!$G$3,IF(AND($N15>='202501'!$E$4,$N15<='202501'!$F$4),'202501'!$G$4,IF(AND($N15>='202501'!$E$5,$N15<='202501'!$F$5),'202501'!$G$5,0)))) -> 0 | S15: =IF(AND($N15>='202502'!$E$2,$N15<='202502'!$F$2),'202502'!$I$2,IF(AND($N15>='202502'!$E$3,$N15<='202502'!$F$3),'202502'!$I$3,IF(AND($N15>='202502'!$E$4,$N15<='202502'!$F$4),'202502'!$I$4,IF(AND($N15>='202502'!$E$5,$N15<='202502'!$F$5),'202502'!$I$5,0)))) -> 4 | T15: =IF(AND($N15>='202502'!$E$2,$N15<='202502'!$F$2),'202502'!$G$2,IF(AND($N15>='202502'!$E$3,$N15<='202502'!$F$3),'202502'!$G$3,IF(AND($N15>='202502'!$E$4,$N15<='202502'!$F$4),'202502'!$G$4,IF(AND($N15>='202502'!$E$5,$N15<='202502'!$F$5),'202502'!$G$5,0)))) -> 0
B16: 13356542 | C16: 133565426 | D16: 13356542-6 | E16: ZEPEDA CASTILLO CRISTIAN | I16: 295605 | L16: =SUM(F16:K16) -> 295605 | M16: 1 | N16: 295605 | O16: =IF(AND($N16>='202401'!$E$2,$N16<='202401'!$F$2),'202401'!$I$2,IF(AND($N16>='202401'!$E$3,$N16<='202401'!$F$3),'202401'!$I$3,IF(AND($N16>='202401'!$E$4,$N16<='202401'!$F$4),'202401'!$I$4,IF(AND($N16>='202401'!$E$5,$N16<='202401'!$F$5),'202401'!$I$5,0)))) -> 1 | P16: =IF(AND($N16>='202401'!$E$2,$N16<='202401'!$F$2),'202401'!$G$2,IF(AND($N16>='202401'!$E$3,$N16<='202401'!$F$3),'202401'!$G$3,IF(AND($N16>='202401'!$E$4,$N16<='202401'!$F$4),'202401'!$G$4,IF(AND($N16>='202401'!$E$5,$N16<='202401'!$F$5),'202401'!$G$5,0)))) -> 21243 | Q16: =IF(AND($N16>='202501'!$E$2,$N16<='202501'!$F$2),'202501'!$I$2,IF(AND($N16>='202501'!$E$3,$N16<='202501'!$F$3),'202501'!$I$3,IF(AND($N16>='202501'!$E$4,$N16<='202501'!$F$4),'202501'!$I$4,IF(AND($N16>='202501'!$E$5,$N16<='202501'!$F$5),'202501'!$I$5,0)))) -> 1 | R16: =IF(AND($N16>='202501'!$E$2,$N16<='202501'!$F$2),'202501'!$G$2,IF(AND($N16>='202501'!$E$3,$N16<='202501'!$F$3),'202501'!$G$3,IF(AND($N16>='202501'!$E$4,$N16<='202501'!$F$4),'202501'!$G$4,IF(AND($N16>='202501'!$E$5,$N16<='202501'!$F$5),'202501'!$G$5,0)))) -> 21243 | S16: =IF(AND($N16>='202502'!$E$2,$N16<='202502'!$F$2),'202502'!$I$2,IF(AND($N16>='202502'!$E$3,$N16<='202502'!$F$3),'202502'!$I$3,IF(AND($N16>='202502'!$E$4,$N16<='202502'!$F$4),'202502'!$I$4,IF(AND($N16>='202502'!$E$5,$N16<='202502'!$F$5),'202502'!$I$5,0)))) -> 1 | T16: =IF(AND($N16>='202502'!$E$2,$N16<='202502'!$F$2),'202502'!$G$2,IF(AND($N16>='202502'!$E$3,$N16<='202502'!$F$3),'202502'!$G$3,IF(AND($N16>='202502'!$E$4,$N16<='202502'!$F$4),'202502'!$G$4,IF(AND($N16>='202502'!$E$5,$N16<='202502'!$F$5),'202502'!$G$5,0)))) -> 22007
B17: 9968254 | C17: 09968254K | D17: 9968254-K | E17: ZEISS CARVALLO ELENA MEGH | F17: 2608096 | G17: 2608096 | H17: 4854805 | I17: 2608096 | J17: 2826314 | K17: 4895875 | L17: =SUM(F17:K17) -> 20401282 | M17: 6 | N17: 3400213 | O17: =IF(AND($N17>='202401'!$E$2,$N17<='202401'!$F$2),'202401'!$I$2,IF(AND($N17>='202401'!$E$3,$N17<='202401'!$F$3),'202401'!$I$3,IF(AND($N17>='202401'!$E$4,$N17<='202401'!$F$4),'202401'!$I$4,IF(AND($N17>='202401'!$E$5,$N17<='202401'!$F$5),'202401'!$I$5,0)))) -> 4 | P17: =IF(AND($N17>='202401'!$E$2,$N17<='202401'!$F$2),'202401'!$G$2,IF(AND($N17>='202401'!$E$3,$N17<='202401'!$F$3),'202401'!$G$3,IF(AND($N17>='202401'!$E$4,$N17<='202401'!$F$4),'202401'!$G$4,IF(AND($N17>='202401'!$E$5,$N17<='202401'!$F$5),'202401'!$G$5,0)))) -> 0 | Q17: =IF(AND($N17>='202501'!$E$2,$N17<='202501'!$F$2),'202501'!$I$2,IF(AND($N17>='202501'!$E$3,$N17<='202501'!$F$3),'202501'!$I$3,IF(AND($N17>='202501'!$E$4,$N17<='202501'!$F$4),'202501'!$I$4,IF(AND($N17>='202501'!$E$5,$N17<='202501'!$F$5),'202501'!$I$5,0)))) -> 4 | R17: =IF(AND($N17>='202501'!$E$2,$N17<='202501'!$F$2),'202501'!$G$2,IF(AND($N17>='202501'!$E$3,$N17<='202501'!$F$3),'202501'!$G$3,IF(AND($N17>='202501'!$E$4,$N17<='202501'!$F$4),'202501'!$G$4,IF(AND($N17>='202501'!$E$5,$N17<='202501'!$F$5),'202501'!$G$5,0)))) -> 0 | S17: =IF(AND($N17>='202502'!$E$2,$N17<='202502'!$F$2),'202502'!$I$2,IF(AND($N17>='202502'!$E$3,$N17<='202502'!$F$3),'202502'!$I$3,IF(AND($N17>='202502'!$E$4,$N17<='202502'!$F$4),'202502'!$I$4,IF(AND($N17>='202502'!$E$5,$N17<='202502'!$F$5),'202502'!$I$5,0)))) -> 4 | T17: =IF(AND($N17>='202502'!$E$2,$N17<='202502'!$F$2),'202502'!$G$2,IF(AND($N17>='202502'!$E$3,$N17<='202502'!$F$3),'202502'!$G$3,IF(AND($N17>='202502'!$E$4,$N17<='202502'!$F$4),'202502'!$G$4,IF(AND($N17>='202502'!$E$5,$N17<='202502'!$F$5),'202502'!$G$5,0)))) -> 0
B18: 17329077 | C18: 173290772 | D18: 17329077-2 | E18: ZAVALA ALLENDE MARÍA IGNACIA | F18: 1848325 | G18: 1848325 | H18: 3499909 | I18: 1848325 | J18: 1848325 | K18: 3511902 | L18: =SUM(F18:K18) -> 14405111 | M18: 6 | N18: 2400851 | O18: =IF(AND($N18>='202401'!$E$2,$N18<='202401'!$F$2),'202401'!$I$2,IF(AND($N18>='202401'!$E$3,$N18<='202401'!$F$3),'202401'!$I$3,IF(AND($N18>='202401'!$E$4,$N18<='202401'!$F$4),'202401'!$I$4,IF(AND($N18>='202401'!$E$5,$N18<='202401'!$F$5),'202401'!$I$5,0)))) -> 4 | P18: =IF(AND($N18>='202401'!$E$2,$N18<='202401'!$F$2),'202401'!$G$2,IF(AND($N18>='202401'!$E$3,$N18<='202401'!$F$3),'202401'!$G$3,IF(AND($N18>='202401'!$E$4,$N18<='202401'!$F$4),'202401'!$G$4,IF(AND($N18>='202401'!$E$5,$N18<='202401'!$F$5),'202401'!$G$5,0)))) -> 0 | Q18: =IF(AND($N18>='202501'!$E$2,$N18<='202501'!$F$2),'202501'!$I$2,IF(AND($N18>='202501'!$E$3,$N18<='202501'!$F$3),'202501'!$I$3,IF(AND($N18>='202501'!$E$4,$N18<='202501'!$F$4),'202501'!$I$4,IF(AND($N18>='202501'!$E$5,$N18<='202501'!$F$5),'202501'!$I$5,0)))) -> 4 | R18: =IF(AND($N18>='202501'!$E$2,$N18<='202501'!$F$2),'202501'!$G$2,IF(AND($N18>='202501'!$E$3,$N18<='202501'!$F$3),'202501'!$G$3,IF(AND($N18>='202501'!$E$4,$N18<='202501'!$F$4),'202501'!$G$4,IF(AND($N18>='202501'!$E$5,$N18<='202501'!$F$5),'202501'!$G$5,0)))) -> 0 | S18: =IF(AND($N18>='202502'!$E$2,$N18<='202502'!$F$2),'202502'!$I$2,IF(AND($N18>='202502'!$E$3,$N18<='202502'!$F$3),'202502'!$I$3,IF(AND($N18>='202502'!$E$4,$N18<='202502'!$F$4),'202502'!$I$4,IF(AND($N18>='202502'!$E$5,$N18<='202502'!$F$5),'202502'!$I$5,0)))) -> 4 | T18: =IF(AND($N18>='202502'!$E$2,$N18<='202502'!$F$2),'202502'!$G$2,IF(AND($N18>='202502'!$E$3,$N18<='202502'!$F$3),'202502'!$G$3,IF(AND($N18>='202502'!$E$4,$N18<='202502'!$F$4),'202502'!$G$4,IF(AND($N18>='202502'!$E$5,$N18<='202502'!$F$5),'202502'!$G$5,0)))) -> 0
